Workbook

Sheet Gear
A1: DataGroup | B1: Gear | J1: (1:라이플, 2:차지, 3: 투척)
A2: id | B2: #group_memo | C2: #name_memo | D2: gear_class | E2: name_id | F2: desc_id | G2: icon | H2: rarity | I2: max_stack | J2: netobject_id
A3: 200000 | B3: 무기 | C3: 맨손 | D3: Weapon | E3: Gear_Name_200000 | F3: Gear_Desc_200000 | G3: icon_weapon_fist | H3: Common | I3: 1 | J3: 1
A4: 210011 | B4: 무기 | C4: 뱅가드_메인1 | D4: Weapon | E4: ="Gear_Name_"&Gear[[#This Row],[id]] | F4: ="Gear_Desc_"&Gear[[#This Row],[id]] | G4: icon_weapon_s1897 | H4: Common | I4: 1 | J4: 1
A5: 210012 | B5: 무기 | C5: 뱅가드_메인2 | D5: Weapon | E5: ="Gear_Name_"&Gear[[#This Row],[id]] | F5: ="Gear_Desc_"&Gear[[#This Row],[id]] | G5: icon_weapon_ump | H5: Common | I5: 1 | J5: 1
A6: 210013 | B6: 무기 | C6: 뱅가드_서브 | D6: Weapon | E6: ="Gear_Name_"&Gear[[#This Row],[id]] | F6: ="Gear_Desc_"&Gear[[#This Row],[id]] | G6: icon_weapon_p92 | H6: Common | I6: 1 | J6: 1
A7: 210014 | B7: 스킬웨폰 | C7: 뱅가드_전술방패 | D7: Weapon | E7: ="Gear_Name_"&Gear[[#This Row],[id]] | F7: ="Gear_Desc_"&Gear[[#This Row],[id]] | G7: null | H7: Common | I7: 1 | J7: 1
A8: 220011 | B8: 무기 | C8: 스트라이커_메인1 | D8: Weapon | E8: ="Gear_Name_"&Gear[[#This Row],[id]] | F8: ="Gear_Desc_"&Gear[[#This Row],[id]] | G8: icon_weapon_m416 | H8: Common | I8: 1 | J8: 1
A9: 220012 | B9: 무기 | C9: 스트라이커_메인2 | D9: Weapon | E9: ="Gear_Name_"&Gear[[#This Row],[id]] | F9: ="Gear_Desc_"&Gear[[#This Row],[id]] | G9: icon_weapon_m249 | H9: Common | I9: 1 | J9: 1
A10: 220013 | B10: 무기 | C10: 스트라이커_서브 | D10: Weapon | E10: ="Gear_Name_"&Gear[[#This Row],[id]] | F10: ="Gear_Desc_"&Gear[[#This Row],[id]] | G10: icon_weapon_deagle | H10: Common | I10: 1 | J10: 1
A11: 220014 | B11: 스킬웨폰 | C11: 스트라이커_궁 | D11: Weapon | E11: ="Gear_Name_"&Gear[[#This Row],[id]] | F11: ="Gear_Desc_"&Gear[[#This Row],[id]] | G11: icon_weapon_striker_rocket_launcher | H11: Rare | I11: 1 | J11: 1
A12: 230011 | B12: 무기 | C12: 에이전트_메인1 | D12: Weapon | E12: ="Gear_Name_"&Gear[[#This Row],[id]] | F12: ="Gear_Desc_"&Gear[[#This Row],[id]] | G12: icon_weapon_vector | H12: Common | I12: 1 | J12: 1
A13: 230012 | B13: 무기 | C13: 에이전트_메인2 | D13: Weapon | E13: ="Gear_Name_"&Gear[[#This Row],[id]] | F13: ="Gear_Desc_"&Gear[[#This Row],[id]] | G13: icon_weapon_awm | H13: Common | I13: 1 | J13: 1
A14: 230013 | B14: 무기 | C14: 에이전트_서브 | D14: Weapon | E14: ="Gear_Name_"&Gear[[#This Row],[id]] | F14: ="Gear_Desc_"&Gear[[#This Row],[id]] | G14: icon_weapon_p1911 | H14: Common | I14: 1 | J14: 1
A15: 230014 | B15: 스킬웨폰 | C15: 에이전트_스킬 | D15: Weapon | E15: ="Gear_Name_"&Gear[[#This Row],[id]] | F15: ="Gear_Desc_"&Gear[[#This Row],[id]] | G15: null | H15: Common | I15: 1 | J15: 1
... A23: 240016 | B23: 스킬웨폰 | C23: 메카닉_스킬_큐브 | D23: Weapon | E23: ="Gear_Name_"&Gear[[#This Row],[id]] | F23: ="Gear_Desc_"&Gear[[#This Row],[id]] | G23: null | H23: Common | I23: 1 | J23: 3
A24: 210021 | B24: 무기(new 테스트) | C24: 뱅가드_메인1 | D24: Weapon | E24: Gear_Name_210011 | F24: Gear_Desc_210011 | G24: icon_weapon_s1897 | H24: Common | I24: 1 | J24: 1
A25: 210022 | B25: 무기(new 테스트) | C25: 뱅가드_메인2 | D25: Weapon | E25: Gear_Name_210012 | F25: Gear_Desc_210012 | G25: icon_weapon_ump | H25: Common | I25: 1 | J25: 1
A26: 210023 | B26: 무기(new 테스트) | C26: 뱅가드_서브 | D26: Weapon | E26: Gear_Name_210013 | F26: Gear_Desc_210013 | G26: icon_weapon_p92 | H26: Common | I26: 1 | J26: 1
A27: 220021 | B27: 무기(new 테스트) | C27: 스트라이커_메인1 | D27: Weapon | E27: Gear_Name_220011 | F27: Gear_Desc_220011 | G27: icon_weapon_m416 | H27: Common | I27: 1 | J27: 1
A28: 220022 | B28: 무기(new 테스트) | C28: 스트라이커_메인2 | D28: Weapon | E28: Gear_Name_220012 | F28: Gear_Desc_220012 | G28: icon_weapon_m249 | H28: Common | I28: 1 | J28: 1
A29: 220023 | B29: 무기(new 테스트) | C29: 스트라이커_서브 | D29: Weapon | E29: Gear_Name_220013 | F29: Gear_Desc_220013 | G29: icon_weapon_deagle | H29: Common | I29: 1 | J29: 1
A30: 220024 | B30: 무기(new 테스트) | C30: 스트라이커_궁 | D30: Weapon | E30: Gear_Name_220014 | F30: Gear_Desc_220014 | G30: icon_weapon_striker_rocket_launcher | H30: Rare | I30: 1 | J30: 1
A31: 230021 | B31: 무기(new 테스트) | C31: 에이전트_메인1 | D31: Weapon | E31: Gear_Name_230011 | F31: Gear_Desc_230011 | G31: icon_weapon_vector | H31: Common | I31: 1 | J31: 1
A32: 230022 | B32: 무기(new 테스트) | C32: 에이전트_메인2 | D32: Weapon | E32: Gear_Name_230012 | F32: Gear_Desc_230012 | G32: icon_weapon_awm | H32: Common | I32: 1 | J32: 1
A33: 230023 | B33: 무기(new 테스트) | C33: 에이전트_서브 | D33: Weapon | E33: Gear_Name_230013 | F33: Gear_Desc_230013 | G33: icon_weapon_p1911 | H33: Common | I33: 1 | J33: 1
A34: 240021 | B34: 무기(new 테스트) | C34: 메카닉_메인1 | D34: Weapon | E34: Gear_Name_240011 | F34: Gear_Desc_240011 | G34: icon_weapon_m16a4 | H34: Common | I34: 1 | J34: 1
A35: 240022 | B35: 무기(new 테스트) | C35: 메카닉_메인2 | D35: Weapon | E35: Gear_Name_240012 | F35: Gear_Desc_240012 | G35: icon_weapon_slr | H35: Common | I35: 1 | J35: 1
A36: 240023 | B36: 무기(new 테스트) | C36: 메카닉_서브 | D36: Weapon | E36: Gear_Name_240013 | F36: Gear_Desc_240013 | G36: icon_weapon_healing_pistol | H36: Common | I36: 1 | J36: 1
A37: 520011 | B37: 무기 | C37: 이두형_메인1 | D37: Weapon | E37: Gear_Name_520011 | F37: Gear_Desc_520011 | G37: icon_weapon_m416 | H37: Common | I37: 1 | J37: 1
A38: 520012 | B38: 무기 | C38: 이두형_메인2 | D38: Weapon | E38: Gear_Name_520012 | F38: Gear_Desc_520012 | G38: icon_weapon_m249 | H38: Common | I38: 1 | J38: 1
A39: 520013 | B39: 무기 | C39: 이두형_서브 | D39: Weapon | E39: Gear_Name_520013 | F39: Gear_Desc_520013 | G39: icon_weapon_deagle | H39: Common | I39: 1 | J39: 1

Sheet Weapon
A1: DataGroup | B1: Weapon | H1: 무기 생성 타입 | I1: projectile_id에게 영향 주지않음 | J1: 대미지 속성 타입 | R1: 그룹id
A2: id | B2: #group_memo | C2: #name_memo | D2: weapon_type | E2: weapon_type_icon | F2: fire_type | G2: ammo_type | H2: source_type | I2: fire_damage_type | J2: elemental_type | K2: aim_mode | L2: penetration_ally | M2: penetration_enemy | N2: penetration_bg | O2: auto_reload | P2: weapon_stat_id | Q2: weapon_self_stat_id | R2: default_skin_id | S2: weapon_fire_setting | T2: projectile_id | U2: passive_id | V2: on_hit_execute_id1 | W2: on_hit_execute_id2 | X2: aim_assist_target | Y2: auto_fire_target | Z2: crosshair_aim | AA2: crosshair_line | AB2: crosshair | AC2: block_move | AD2: block_jump | AE2: is_swap_clear | AF2: force_stance | AG2: force_aim | AH2: base_rotation_mode | AI2: block_jump_state | AJ2: camera_setting_stand_hip | AK2: camera_setting_stand_hip_fire | AL2: camera_setting_stand_aim | AM2: camera_setting_stand_ads | AN2: camera_setting_crouch_hip | AO2: camera_setting_crouch_hip_fire | AP2: camera_setting_crouch_aim | AQ2: camera_setting_crouch_ads | AR2: vinette_setting | AS2: autofire_condition | AT2: initial_aim_assist_state | AU2: initial_auto_fire_state
A3: 210011 | B3: 프리드웬_메인1 | C3: SG_토르 | D3: SG | E3: icon_weapontype_sg | F3: Auto | G3: Bullet | H3: Normal | I3: Damage | J3: Bullet | K3: Aim | L3: 1 | M3: 0 | N3: 0 | O3: 1 | P3: 210011 | Q3: -1 | R3: 210011 | S3: WeaponFireSettings_sg_thor_Default | X3: Enemy | Y3: Enemy | Z3: Cross | AA3: RoundedEdge | AC3: 0 | AD3: 0 | AE3: 0 | AG3: None | AH3: None | AI3: 0 | AJ3: CameraSettings_Stand_Default | AK3: CameraSettings_Stand_HipFire | AL3: CameraSettings_Stand_Aim | AM3: CameraSettings_Stand_Ads | AN3: CameraSettings_Crouch_Default | AO3: CameraSettings_Crouch_HipFire | AP3: CameraSettings_Crouch_Aim | AQ3: CameraSettings_Crouch_Ads | AS3: Always
A4: 210012 | B4: 프리드웬_메인2 | C4: SMG_벨리알 | D4: SMG | E4: icon_weapontype_smg | F4: Auto | G4: Bullet | H4: Normal | I4: Damage | J4: Bullet | K4: Aim | L4: 1 | M4: 0 | N4: 0 | O4: 1 | P4: 210012 | Q4: -1 | R4: 210012 | S4: WeaponFireSettings_smg_belial_Default | X4: Enemy | Y4: Enemy | Z4: Cross | AA4: RoundedEdge | AC4: 0 | AD4: 0 | AE4: 0 | AG4: None | AH4: None | AI4: 0 | AJ4: CameraSettings_Stand_Default | AK4: CameraSettings_Stand_HipFire | AL4: CameraSettings_Stand_Aim | AM4: CameraSettings_Stand_Ads | AN4: CameraSettings_Crouch_Default | AO4: CameraSettings_Crouch_HipFire | AP4: CameraSettings_Crouch_Aim | AQ4: CameraSettings_Crouch_Ads | AS4: Always
A5: 210013 | B5: 프리드웬_서브 | C5: HG_니케 | D5: HG | E5: icon_weapontype_hg | F5: Auto | G5: Bullet | H5: Normal | I5: Damage | J5: Bullet | K5: Aim | L5: 1 | M5: 0 | N5: 0 | O5: 1 | P5: 210013 | Q5: -1 | R5: 210013 | S5: WeaponFireSettings_hg_nike_Default | X5: Enemy | Y5: Enemy | Z5: Cross | AA5: RoundedEdge | AC5: 0 | AD5: 0 | AE5: 0 | AG5: None | AH5: None | AI5: 0 | AJ5: CameraSettings_Stand_Default | AK5: CameraSettings_Stand_HipFire | AL5: CameraSettings_Stand_Aim | AM5: CameraSettings_Stand_Ads | AN5: CameraSettings_Crouch_Default | AO5: CameraSettings_Crouch_HipFire | AP5: CameraSettings_Crouch_Aim | AQ5: CameraSettings_Crouch_Ads | AS5: Always
A6: 210014 | B6: 프리드웬_전술방패 | C6: Skill_전술방패 | D6: Shield | E6: icon_weapontype_shield | H6: SkillWeapon | L6: 0 | M6: 0 | N6: 0 | O6: 1 | P6: 210014 | Q6: 210014 | R6: 210014 | X6: Enemy | Y6: Enemy | Z6: Cross | AA6: RoundedEdge | AC6: 0 | AD6: 1 | AE6: 0 | AF6: Stand | AG6: None | AH6: OrientRotationToCamera | AI6: 1 | AJ6: CameraSettings_Skill_Shield | AK6: CameraSettings_Skill_Shield | AL6: CameraSettings_Skill_Shield | AM6: CameraSettings_Skill_Shield | AN6: CameraSettings_Skill_Shield | AO6: CameraSettings_Skill_Shield | AP6: CameraSettings_Skill_Shield | AQ6: CameraSettings_Skill_Shield
A7: 220011 | B7: 카야_메인1 | C7: AR_스위프트 | D7: AR | E7: icon_weapontype_ar | F7: Auto | G7: Bullet | H7: Normal | I7: Damage | J7: Bullet | K7: Aim | L7: 1 | M7: 0 | N7: 0 | O7: 1 | P7: 220011 | Q7: -1 | R7: 220011 | S7: WeaponFireSettings_ar_swift_Default | X7: Enemy | Y7: Enemy | Z7: Cross | AA7: RoundedEdge | AC7: 0 | AD7: 0 | AE7: 0 | AG7: None | AH7: None | AI7: 0 | AJ7: CameraSettings_Stand_Default | AK7: CameraSettings_Stand_HipFire | AL7: CameraSettings_Stand_Aim | AM7: CameraSettings_Stand_Ads | AN7: CameraSettings_Crouch_Default | AO7: CameraSettings_Crouch_HipFire | AP7: CameraSettings_Crouch_Aim | AQ7: CameraSettings_Crouch_Ads | AS7: Always
A8: 220012 | B8: 카야_메인2 | C8: LMG_그리즐리 | D8: LMG | E8: icon_weapontype_lmg | F8: Auto | G8: Bullet | H8: Normal | I8: Damage | J8: Bullet | K8: Aim | L8: 1 | M8: 0 | N8: 0 | O8: 1 | P8: 220012 | Q8: -1 | R8: 220012 | S8: WeaponFireSettings_lmg_grizzly_Default | X8: Enemy | Y8: Enemy | Z8: Cross | AA8: RoundedEdge | AC8: 0 | AD8: 0 | AE8: 0 | AG8: None | AH8: None | AI8: 0 | AJ8: CameraSettings_Stand_Default | AK8: CameraSettings_Stand_HipFire | AL8: CameraSettings_Stand_Aim | AM8: CameraSettings_Stand_Ads | AN8: CameraSettings_Crouch_Default | AO8: CameraSettings_Crouch_HipFire | AP8: CameraSettings_Crouch_Aim | AQ8: CameraSettings_Crouch_Ads | AS8: Always
A9: 220013 | B9: 카야_서브 | C9: HG_헤라 | D9: HG | E9: icon_weapontype_hg | F9: Auto | G9: Bullet | H9: Normal | I9: Damage | J9: Bullet | K9: Aim | L9: 1 | M9: 0 | N9: 0 | O9: 1 | P9: 220013 | Q9: -1 | R9: 220013 | S9: WeaponFireSettings_hg_hera_Default | X9: Enemy | Y9: Enemy | Z9: Cross | AA9: RoundedEdge | AC9: 0 | AD9: 0 | AE9: 0 | AG9: None | AH9: None | AI9: 0 | AJ9: CameraSettings_Stand_Default | AK9: CameraSettings_Stand_HipFire | AL9: CameraSettings_Stand_Aim | AM9: CameraSettings_Stand_Ads | AN9: CameraSettings_Crouch_Default | AO9: CameraSettings_Crouch_HipFire | AP9: CameraSettings_Crouch_Aim | AQ9: CameraSettings_Crouch_Ads | AS9: Always
A10: 220014 | B10: 카야_궁 | C10: Skill_대전차로켓 | D10: Special | E10: icon_weapontype_special | F10: Auto | H10: SkillWeapon | I10: Damage | J10: Splash | K10: Aim | L10: 1 | M10: 0 | N10: 0 | O10: 1 | P10: 220014 | Q10: -1 | R10: 220014 | S10: WeaponFireSettings_sw_striker_rocket_launcher_Default | T10: 2200141 | U10: 200130 | X10: None | Y10: Enemy | Z10: Launcher | AA10: None | AB10: crosshair_launcher | AC10: 0 | AD10: 1 | AE10: 1 | AG10: Aim | AH10: None | AI10: 0 | AJ10: CameraSettings_Stand_Aim_RocketLauncher | AK10: CameraSettings_Stand_Aim_RocketLauncher | AL10: CameraSettings_Stand_Aim_RocketLauncher | AM10: CameraSettings_Stand_Aim_RocketLauncher | AN10: CameraSettings_Crouch_Aim_RocketLauncher | AO10: CameraSettings_Crouch_Aim_RocketLauncher | AP10: CameraSettings_Crouch_Aim_RocketLauncher | AQ10: CameraSettings_Crouch_Aim_RocketLauncher | AR10: VignetteSettings_Weapon_RocketLauncher | AS10: Always
A11: 230011 | B11: 엔젤_메인1 | C11: SMG_아스타로트 | D11: SMG | E11: icon_weapontype_smg | F11: Auto | G11: Bullet | H11: Normal | I11: Damage | J11: Bullet | K11: Aim | L11: 1 | M11: 0 | N11: 0 | O11: 1 | P11: 230011 | Q11: -1 | R11: 230011 | S11: WeaponFireSettings_smg_vector_Default | X11: Enemy | Y11: Enemy | Z11: Cross | AA11: RoundedEdge | AC11: 0 | AD11: 0 | AE11: 0 | AG11: None | AH11: None | AI11: 0 | AJ11: CameraSettings_Stand_Default | AK11: CameraSettings_Stand_HipFire | AL11: CameraSettings_Stand_Aim | AM11: CameraSettings_Stand_Ads | AN11: CameraSettings_Crouch_Default | AO11: CameraSettings_Crouch_HipFire | AP11: CameraSettings_Crouch_Aim | AQ11: CameraSettings_Crouch_Ads | AS11: Always
A12: 230012 | B12: 엔젤_메인2 | C12: SR_도미니온 | D12: SR | E12: icon_weapontype_sr | F12: Semi | G12: Bullet | H12: Normal | I12: Damage | J12: Bullet | K12: Ads | L12: 1 | M12: 0 | N12: 0 | O12: 1 | P12: 230012 | Q12: -1 | R12: 230012 | S12: WeaponFireSettings_sr_awm_Default | X12: Enemy | Y12: Enemy | Z12: Cross | AA12: RoundedEdge | AC12: 0 | AD12: 0 | AE12: 0 | AG12: None | AH12: None | AI12: 0 | AJ12: CameraSettings_Stand_Default | AK12: CameraSettings_Stand_HipFire | AL12: CameraSettings_Stand_Aim | AM12: CameraSettings_Stand_Ads | AN12: CameraSettings_Crouch_Default | AO12: CameraSettings_Crouch_HipFire | AP12: CameraSettings_Crouch_Aim | AQ12: CameraSettings_Crouch_Ads | AS12: ADS
A13: 230013 | B13: 엔젤_서브 | C13: HG_스카디 | D13: HG | E13: icon_weapontype_hg | F13: Auto | G13: Bullet | H13: Normal | I13: Damage | J13: Bullet | K13: Aim | L13: 1 | M13: 0 | N13: 0 | O13: 1 | P13: 230013 | Q13: -1 | R13: 230013 | S13: WeaponFireSettings_hg_p1911_Default | X13: Enemy | Y13: Enemy | Z13: Cross | AA13: RoundedEdge | AC13: 0 | AD13: 0 | AE13: 0 | AG13: None | AH13: None | AI13: 0 | AJ13: CameraSettings_Stand_Default | AK13: CameraSettings_Stand_HipFire | AL13: CameraSettings_Stand_Aim | AM13: CameraSettings_Stand_Ads | AN13: CameraSettings_Crouch_Default | AO13: CameraSettings_Crouch_HipFire | AP13: CameraSettings_Crouch_Aim | AQ13: CameraSettings_Crouch_Ads | AS13: Always
A14: 230014 | B14: 엔젤_스킬 | C14: Skill_오프라인암기 | D14: Special | E14: icon_weapontype_special | F14: Semi | G14: Bullet | H14: SkillWeapon | I14: Damage | J14: Bullet | K14: Aim | L14: 1 | M14: 0 | N14: 0 | O14: 1 | P14: 230014 | Q14: -1 | R14: 230014 | S14: WeaponFireSettings_sw_angel_offline_Default | T14: 2300141 | X14: Enemy | Y14: None | Z14: Cross | AA14: RoundedEdge | AC14: 0 | AD14: 0 | AE14: 1 | AG14: None | AH14: None | AI14: 0 | AJ14: CameraSettings_Stand_Default | AK14: CameraSettings_Stand_HipFire | AL14: CameraSettings_Stand_Aim | AM14: CameraSettings_Stand_Ads | AN14: CameraSettings_Crouch_Default | AO14: CameraSettings_Crouch_HipFire | AP14: CameraSettings_Crouch_Aim | AQ14: CameraSettings_Crouch_Ads
A15: 230015 | B15: 엔젤_궁 | C15: Skill_지명수배저격 | D15: LockOnCharge | E15: icon_weapontype_special | F15: Semi | G15: Bullet | H15: SkillWeapon | I15: Damage | J15: Bullet | K15: Ads | L15: 1 | M15: 1 | N15: 1 | O15: 1 | P15: 230015 | Q15: -1 | R15: 230015 | S15: WeaponFireSettings_sw_angel_wanted_Default | U15: 300130 | X15: Enemy | Y15: Enemy | Z15: Launcher | AA15: None | AB15: crosshair_launcher | AC15: 1 | AD15: 1 | AE15: 1 | AF15: Crouch | AG15: Ads | AH15: OrientRotationToCamera | AI15: 1 | AJ15: CameraSettings_Stand_Default | AK15: CameraSettings_Stand_HipFire | AL15: CameraSettings_Stand_Aim | AM15: CameraSettings_Stand_Ads | AN15: CameraSettings_Crouch_Default | AO15: CameraSettings_Crouch_HipFire | AP15: CameraSettings_Crouch_Aim | AQ15: CameraSettings_Crouch_Ads
A16: 230016 | B16: 엔젤_스킬 | C16: 구m67-(임시) | D16: Throwable | E16: icon_weapontype_throwable | F16: Throwable | H16: SkillWeapon | I16: Damage | J16: Splash | K16: Hip | L16: 0 | M16: 0 | N16: 0 | O16: 1 | P16: 230016 | Q16: -1 | R16: 230016 | S16: WeaponFireSettings_gr_m67_Default | T16: 2300161 | X16: Enemy | Y16: Enemy | Z16: Cross | AA16: RoundedEdge | AC16: 0 | AD16: 0 | AE16: 0 | AG16: None | AH16: None | AI16: 0 | AJ16: CameraSettings_Stand_Default | AK16: CameraSettings_Stand_HipFire_Throw | AL16: CameraSettings_Stand_Aim_Throw | AM16: CameraSettings_Stand_Ads_Throw | AN16: CameraSettings_Crouch_Default | AO16: CameraSettings_Crouch_HipFire_Throw | AP16: CameraSettings_Crouch_Aim_Throw | AQ16: CameraSettings_Crouch_Ads_Throw | AS16: Always
A17: 240011 | B17: 시냅스_메인1 | C17: AR_케스트럴 | D17: AR | E17: icon_weapontype_ar | F17: Auto | G17: Bullet | H17: Normal | I17: Damage | J17: Bullet | K17: Aim | L17: 1 | M17: 0 | N17: 0 | O17: 1 | P17: 240011 | Q17: -1 | R17: 240011 | S17: WeaponFireSettings_ar_m16a4_Default | X17: Enemy | Y17: Enemy | Z17: Cross | AA17: RoundedEdge | AC17: 0 | AD17: 0 | AE17: 0 | AG17: None | AH17: None | AI17: 0 | AJ17: CameraSettings_Stand_Default | AK17: CameraSettings_Stand_HipFire | AL17: CameraSettings_Stand_Aim | AM17: CameraSettings_Stand_Ads | AN17: CameraSettings_Crouch_Default | AO17: CameraSettings_Crouch_HipFire | AP17: CameraSettings_Crouch_Aim | AQ17: CameraSettings_Crouch_Ads | AS17: Always
A18: 240012 | B18: 시냅스_메인2 | C18: DMR_멀릿 | D18: PreCharge | E18: icon_weapontype_dmr | F18: Auto | G18: Bullet | H18: Normal | I18: Damage | J18: Bullet | K18: Ads | L18: 1 | M18: 0 | N18: 0 | O18: 1 | P18: 240012 | Q18: -1 | R18: 240012 | S18: WeaponFireSettings_dmr_slr_Default | X18: Enemy | Y18: Enemy | Z18: Cross | AA18: RoundedEdge | AC18: 0 | AD18: 0 | AE18: 0 | AG18: None | AH18: None | AI18: 0 | AJ18: CameraSettings_Stand_Default | AK18: CameraSettings_Stand_HipFire | AL18: CameraSettings_Stand_Aim | AM18: CameraSettings_Stand_Ads | AN18: CameraSettings_Crouch_Default | AO18: CameraSettings_Crouch_HipFire | AP18: CameraSettings_Crouch_Aim | AQ18: CameraSettings_Crouch_Ads | AS18: Always
A19: 240013 | B19: 시냅스_서브 | C19: HG_주노 | D19: Special | E19: icon_weapontype_special | F19: Semi | H19: Normal | I19: Heal | K19: Aim | L19: 0 | M19: 1 | N19: 0 | O19: 1 | P19: 240013 | Q19: -1 | R19: 240013 | S19: WeaponFireSettings_hg_healing_pistol_Default | X19: Ally | Y19: Ally | Z19: Cross | AA19: RoundedEdge | AC19: 0 | AD19: 0 | AE19: 0 | AG19: None | AH19: None | AI19: 0 | AJ19: CameraSettings_Stand_Default | AK19: CameraSettings_Stand_HipFire | AL19: CameraSettings_Stand_Aim | AM19: CameraSettings_Stand_Ads | AN19: CameraSettings_Crouch_Default | AO19: CameraSettings_Crouch_HipFire | AP19: CameraSettings_Crouch_Aim | AQ19: CameraSettings_Crouch_Ads | AS19: Always
A20: 240014 | B20: 시냅스_스킬 | C20: Skill_방해전파장치 | D20: Special | E20: icon_weapontype_throwable | F20: Semi | H20: SkillWeapon | J20: Splash | K20: Hip | L20: 1 | M20: 0 | N20: 0 | O20: 1 | P20: 240014 | Q20: -1 | R20: 240014 | S20: WeaponFireSettings_sw_synapse_jammer | T20: 2400141 | V20: 4001102 | W20: 4001103 | X20: None | Y20: None | Z20: Cross | AA20: None | AC20: 0 | AD20: 0 | AE20: 1 | AG20: None | AH20: None | AI20: 0 | AJ20: CameraSettings_Stand_Default | AK20: CameraSettings_Stand_HipFire | AL20: CameraSettings_Stand_Aim | AM20: CameraSettings_Stand_Ads | AN20: CameraSettings_Crouch_Default | AO20: CameraSettings_Crouch_HipFire | AP20: CameraSettings_Crouch_Aim | AQ20: CameraSettings_Crouch_Ads
A21: 240015 | B21: 시냅스_궁 | C21: Skill_바이러스노드 | D21: Special | E21: icon_weapontype_throwable | F21: Semi | H21: SkillWeapon | J21: Splash | K21: Hip | L21: 1 | M21: 0 | N21: 0 | O21: 1 | P21: 240015 | Q21: -1 | R21: 240015 | S21: WeaponFireSettings_sw_synapse_virusnode | T21: 2400151 | X21: None | Y21: None | Z21: Launcher | AA21: None | AB21: crosshair_launcher | AC21: 0 | AD21: 0 | AE21: 1 | AG21: None | AH21: None | AI21: 0 | AJ21: CameraSettings_Stand_Default | AK21: CameraSettings_Stand_HipFire | AL21: CameraSettings_Stand_Aim | AM21: CameraSettings_Stand_Ads | AN21: CameraSettings_Crouch_Default | AO21: CameraSettings_Crouch_HipFire | AP21: CameraSettings_Crouch_Aim | AQ21: CameraSettings_Crouch_Ads
A22: 240016 | B22: 시냅스_스킬 | C22: 큐브설치-(임시) | D22: Throwable | E22: icon_weapontype_throwable | F22: Throwable | H22: SkillWeapon | I22: Damage | K22: Ads | L22: 0 | M22: 0 | N22: 0 | O22: 1 | P22: 240016 | Q22: -1 | R22: 240016 | S22: WeaponFireSettings_sw_protect_cub | T22: 410111 | V22: 4001103 | X22: Enemy | Y22: Enemy | Z22: Cross | AA22: None | AC22: 0 | AD22: 0 | AE22: 1 | AG22: None | AH22: None | AI22: 0 | AJ22: CameraSettings_Stand_Default | AK22: CameraSettings_Stand_HipFire_Throw | AL22: CameraSettings_Stand_Aim_Throw | AM22: CameraSettings_Stand_Ads_Throw | AN22: CameraSettings_Crouch_Default | AO22: CameraSettings_Crouch_HipFire_Throw | AP22: CameraSettings_Crouch_Aim_Throw | AQ22: CameraSettings_Crouch_Ads_Throw
A23: 210021 | B23: 프리드웬_메인1 | C23: S1897-토르 | D23: SG | E23: icon_weapontype_sg | F23: Auto | G23: Bullet | H23: Normal | I23: Damage | J23: Bullet | K23: Aim | L23: 1 | M23: 0 | N23: 0 | O23: 1 | P23: 210011 | Q23: -1 | R23: 210021 | S23: WeaponFireSettings_sg_s1897_Default | X23: Enemy | Y23: Enemy | Z23: Cross | AA23: RoundedEdge | AC23: 0 | AD23: 0 | AE23: 0 | AG23: None | AH23: None | AI23: 0 | AJ23: CameraSettings_Stand_Default | AK23: CameraSettings_Stand_HipFire | AL23: CameraSettings_Stand_Aim | AM23: CameraSettings_Stand_Ads | AN23: CameraSettings_Crouch_Default | AO23: CameraSettings_Crouch_HipFire | AP23: CameraSettings_Crouch_Aim | AQ23: CameraSettings_Crouch_Ads | AS23: Always
A24: 210022 | B24: 프리드웬_메인2 | C24: UMP-벨리알 | D24: SMG | E24: icon_weapontype_smg | F24: Auto | G24: Bullet | H24: Normal | I24: Damage | J24: Bullet | K24: Aim | L24: 1 | M24: 0 | N24: 0 | O24: 1 | P24: 210012 | Q24: -1 | R24: 210022 | S24: WeaponFireSettings_smg_ump_Default | X24: Enemy | Y24: Enemy | Z24: Cross | AA24: RoundedEdge | AC24: 0 | AD24: 0 | AE24: 0 | AG24: None | AH24: None | AI24: 0 | AJ24: CameraSettings_Stand_Default | AK24: CameraSettings_Stand_HipFire | AL24: CameraSettings_Stand_Aim | AM24: CameraSettings_Stand_Ads | AN24: CameraSettings_Crouch_Default | AO24: CameraSettings_Crouch_HipFire | AP24: CameraSettings_Crouch_Aim | AQ24: CameraSettings_Crouch_Ads | AS24: Always
A25: 210023 | B25: 프리드웬_서브 | C25: P92-니케 | D25: HG | E25: icon_weapontype_hg | F25: Auto | G25: Bullet | H25: Normal | I25: Damage | J25: Bullet | K25: Aim | L25: 1 | M25: 0 | N25: 0 | O25: 1 | P25: 210013 | Q25: -1 | R25: 210023 | S25: WeaponFireSettings_hg_p92_Default | X25: Enemy | Y25: Enemy | Z25: Cross | AA25: RoundedEdge | AC25: 0 | AD25: 0 | AE25: 0 | AG25: None | AH25: None | AI25: 0 | AJ25: CameraSettings_Stand_Default | AK25: CameraSettings_Stand_HipFire | AL25: CameraSettings_Stand_Aim | AM25: CameraSettings_Stand_Ads | AN25: CameraSettings_Crouch_Default | AO25: CameraSettings_Crouch_HipFire | AP25: CameraSettings_Crouch_Aim | AQ25: CameraSettings_Crouch_Ads | AS25: Always
A26: 220021 | B26: 카야_메인1 | C26: M416-스위프트 | D26: AR | E26: icon_weapontype_ar | F26: Auto | G26: Bullet | H26: Normal | I26: Damage | J26: Bullet | K26: Aim | L26: 1 | M26: 0 | N26: 0 | O26: 1 | P26: 220011 | Q26: -1 | R26: 220021 | S26: WeaponFireSettings_ar_m416_Default | X26: Enemy | Y26: Enemy | Z26: Cross | AA26: RoundedEdge | AC26: 0 | AD26: 0 | AE26: 0 | AG26: None | AH26: None | AI26: 0 | AJ26: CameraSettings_Stand_Default | AK26: CameraSettings_Stand_HipFire | AL26: CameraSettings_Stand_Aim | AM26: CameraSettings_Stand_Ads | AN26: CameraSettings_Crouch_Default | AO26: CameraSettings_Crouch_HipFire | AP26: CameraSettings_Crouch_Aim | AQ26: CameraSettings_Crouch_Ads | AS26: Always
A27: 220022 | B27: 카야_메인2 | C27: M249-그리즐리 | D27: LMG | E27: icon_weapontype_lmg | F27: Auto | G27: Bullet | H27: Normal | I27: Damage | J27: Bullet | K27: Aim | L27: 1 | M27: 0 | N27: 0 | O27: 1 | P27: 220012 | Q27: -1 | R27: 220022 | S27: WeaponFireSettings_lmg_m249_Default | X27: Enemy | Y27: Enemy | Z27: Cross | AA27: RoundedEdge | AC27: 0 | AD27: 0 | AE27: 0 | AG27: None | AH27: None | AI27: 0 | AJ27: CameraSettings_Stand_Default | AK27: CameraSettings_Stand_HipFire | AL27: CameraSettings_Stand_Aim | AM27: CameraSettings_Stand_Ads | AN27: CameraSettings_Crouch_Default | AO27: CameraSettings_Crouch_HipFire | AP27: CameraSettings_Crouch_Aim | AQ27: CameraSettings_Crouch_Ads | AS27: Always
A28: 220023 | B28: 카야_서브 | C28: Deagle-헤라 | D28: HG | E28: icon_weapontype_hg | F28: Auto | G28: Bullet | H28: Normal | I28: Damage | J28: Bullet | K28: Aim | L28: 1 | M28: 0 | N28: 0 | O28: 1 | P28: 220013 | Q28: -1 | R28: 220023 | S28: WeaponFireSettings_hg_deagle_Default | X28: Enemy | Y28: Enemy | Z28: Cross | AA28: RoundedEdge | AC28: 0 | AD28: 0 | AE28: 0 | AG28: None | AH28: None | AI28: 0 | AJ28: CameraSettings_Stand_Default | AK28: CameraSettings_Stand_HipFire | AL28: CameraSettings_Stand_Aim | AM28: CameraSettings_Stand_Ads | AN28: CameraSettings_Crouch_Default | AO28: CameraSettings_Crouch_HipFire | AP28: CameraSettings_Crouch_Aim | AQ28: CameraSettings_Crouch_Ads | AS28: Always
A29: 220024 | B29: 카야_궁 | C29: striker_rocket_launcher-판처파우스트 | D29: Special | E29: icon_weapontype_special | F29: Auto | H29: SkillWeapon | I29: Damage | J29: Splash | K29: Aim | L29: 1 | M29: 0 | N29: 0 | O29: 1 | P29: 220014 | Q29: -1 | R29: 220024 | S29: WeaponFireSettings_striker_rocket_launcher | T29: 2200141 | U29: 200130 | X29: None | Y29: Enemy | Z29: Launcher | AA29: None | AB29: crosshair_launcher | AC29: 0 | AD29: 1 | AE29: 1 | AG29: Aim | AH29: None | AI29: 0 | AJ29: CameraSettings_Stand_Aim_RocketLauncher | AK29: CameraSettings_Stand_Aim_RocketLauncher | AL29: CameraSettings_Stand_Aim_RocketLauncher | AM29: CameraSettings_Stand_Aim_RocketLauncher | AN29: CameraSettings_Crouch_Aim_RocketLauncher | AO29: CameraSettings_Crouch_Aim_RocketLauncher | AP29: CameraSettings_Crouch_Aim_RocketLauncher | AQ29: CameraSettings_Crouch_Aim_RocketLauncher | AR29: VignetteSettings_Weapon_RocketLauncher | AS29: Always
A30: 230021 | B30: 엔젤_메인1 | C30: Vector-아스타로트 | D30: SMG | E30: icon_weapontype_smg | F30: Auto | G30: Bullet | H30: Normal | I30: Damage | J30: Bullet | K30: Aim | L30: 1 | M30: 0 | N30: 0 | O30: 1 | P30: 230011 | Q30: -1 | R30: 230021 | S30: WeaponFireSettings_smg_vector_Default | X30: Enemy | Y30: Enemy | Z30: Cross | AA30: RoundedEdge | AC30: 0 | AD30: 0 | AE30: 0 | AG30: None | AH30: None | AI30: 0 | AJ30: CameraSettings_Stand_Default | AK30: CameraSettings_Stand_HipFire | AL30: CameraSettings_Stand_Aim | AM30: CameraSettings_Stand_Ads | AN30: CameraSettings_Crouch_Default | AO30: CameraSettings_Crouch_HipFire | AP30: CameraSettings_Crouch_Aim | AQ30: CameraSettings_Crouch_Ads | AS30: Always
A31: 230022 | B31: 엔젤_메인2 | C31: AWM-도미니온 | D31: SR | E31: icon_weapontype_sr | F31: Semi | G31: Bullet | H31: Normal | I31: Damage | J31: Bullet | K31: Ads | L31: 1 | M31: 0 | N31: 0 | O31: 1 | P31: 230012 | Q31: -1 | R31: 230022 | S31: WeaponFireSettings_sr_awm_Default | X31: Enemy | Y31: Enemy | Z31: Cross | AA31: RoundedEdge | AC31: 0 | AD31: 0 | AE31: 0 | AG31: None | AH31: None | AI31: 0 | AJ31: CameraSettings_Stand_Default | AK31: CameraSettings_Stand_HipFire | AL31: CameraSettings_Stand_Aim | AM31: CameraSettings_Stand_Ads | AN31: CameraSettings_Crouch_Default | AO31: CameraSettings_Crouch_HipFire | AP31: CameraSettings_Crouch_Aim | AQ31: CameraSettings_Crouch_Ads | AS31: ADS
A32: 230023 | B32: 엔젤_서브 | C32: P1911-스카디 | D32: HG | E32: icon_weapontype_hg | F32: Auto | G32: Bullet | H32: Normal | I32: Damage | J32: Bullet | K32: Aim | L32: 1 | M32: 0 | N32: 0 | O32: 1 | P32: 230013 | Q32: -1 | R32: 230023 | S32: WeaponFireSettings_hg_p1911_Default | X32: Enemy | Y32: Enemy | Z32: Cross | AA32: RoundedEdge | AC32: 0 | AD32: 0 | AE32: 0 | AG32: None | AH32: None | AI32: 0 | AJ32: CameraSettings_Stand_Default | AK32: CameraSettings_Stand_HipFire | AL32: CameraSettings_Stand_Aim | AM32: CameraSettings_Stand_Ads | AN32: CameraSettings_Crouch_Default | AO32: CameraSettings_Crouch_HipFire | AP32: CameraSettings_Crouch_Aim | AQ32: CameraSettings_Crouch_Ads | AS32: Always
A33: 240021 | B33: 시냅스_메인1 | C33: M16A4-케스트럴 | D33: AR | E33: icon_weapontype_ar | F33: Auto | G33: Bullet | H33: Normal | I33: Damage | J33: Bullet | K33: Aim | L33: 1 | M33: 0 | N33: 0 | O33: 1 | P33: 240011 | Q33: -1 | R33: 240021 | S33: WeaponFireSettings_ar_m16a4_Default | X33: Enemy | Y33: Enemy | Z33: Cross | AA33: RoundedEdge | AC33: 0 | AD33: 0 | AE33: 0 | AG33: None | AH33: None | AI33: 0 | AJ33: CameraSettings_Stand_Default | AK33: CameraSettings_Stand_HipFire | AL33: CameraSettings_Stand_Aim | AM33: CameraSettings_Stand_Ads | AN33: CameraSettings_Crouch_Default | AO33: CameraSettings_Crouch_HipFire | AP33: CameraSettings_Crouch_Aim | AQ33: CameraSettings_Crouch_Ads | AS33: Always
A34: 240022 | B34: 시냅스_메인2 | C34: SLR-멀릿 | D34: DMR | E34: icon_weapontype_dmr | F34: Auto | G34: Bullet | H34: Normal | I34: Damage | J34: Bullet | K34: Ads | L34: 1 | M34: 0 | N34: 0 | O34: 1 | P34: 240012 | Q34: -1 | R34: 240022 | S34: WeaponFireSettings_dmr_slr_Default | X34: Enemy | Y34: Enemy | Z34: Cross | AA34: RoundedEdge | AC34: 0 | AD34: 0 | AE34: 0 | AG34: None | AH34: None | AI34: 0 | AJ34: CameraSettings_Stand_Default | AK34: CameraSettings_Stand_HipFire | AL34: CameraSettings_Stand_Aim | AM34: CameraSettings_Stand_Ads | AN34: CameraSettings_Crouch_Default | AO34: CameraSettings_Crouch_HipFire | AP34: CameraSettings_Crouch_Aim | AQ34: CameraSettings_Crouch_Ads | AS34: Always
A35: 240023 | B35: 시냅스_서브 | C35: healing_pistol-주노 | D35: Special | E35: icon_weapontype_special | F35: Semi | H35: Normal | I35: Heal | K35: Aim | L35: 0 | M35: 1 | N35: 0 | O35: 1 | P35: 240013 | Q35: -1 | R35: 240023 | S35: WeaponFireSettings_hg_healing_pistol_Default | X35: Ally | Y35: Ally | Z35: Cross | AA35: RoundedEdge | AC35: 0 | AD35: 0 | AE35: 0 | AG35: None | AH35: None | AI35: 0 | AJ35: CameraSettings_Stand_Default | AK35: CameraSettings_Stand_HipFire | AL35: CameraSettings_Stand_Aim | AM35: CameraSettings_Stand_Ads | AN35: CameraSettings_Crouch_Default | AO35: CameraSettings_Crouch_HipFire | AP35: CameraSettings_Crouch_Aim | AQ35: CameraSettings_Crouch_Ads | AS35: Always

Sheet WeaponStat
A1: DataGroup | B1: WeaponStat
A2: id | B2: #group_memo | C2: #name_memo | D2: damage_base | E2: damage_head_modifier | F2: damage_body_modifier | G2: damage_limb_modifier | H2: damage_shield_modifier | I2: damage_self_value | J2: damage_ally_value | K2: damage_enemy_value | L2: heal_base | M2: fire_rate | N2: effective_range | O2: damage_falloff_start_distance | P2: damage_falloff_end_distance | Q2: damage_falloff_min_value | R2: mag_capacity_1 | S2: mag_capacity_2 | T2: mag_capacity_3 | U2: no_anim_reload_time | V2: reload_time | W2: ammo_amount_spawn | X2: ammo_amount_airdrop | Y2: move_speed | Z2: move_speed_rate_stand_hip | AA2: move_speed_rate_stand_hip_fire | AB2: move_speed_rate_stand_aim | AC2: move_speed_rate_stand_ads | AD2: move_speed_rate_stand_reload | AE2: move_speed_rate_stand_equip | AF2: move_speed_rate_crouch_hip | AG2: move_speed_rate_crouch_hip_fire | AH2: move_speed_rate_crouch_aim | AI2: move_speed_rate_crouch_ads | AJ2: move_speed_rate_crouch_reload | AK2: move_speed_rate_crouch_equip | AL2: deviation_standing | AM2: deviation_crouch | AN2: deviation_rate_aim | AO2: deviation_rate_ads | AP2: deviation_rate_move | AQ2: deviation_rate_jump | AR2: moa_base | AS2: moa_max | AT2: moa_increment_per_shot | AU2: moa_bonus_shot_count | AV2: moa_bonus_reset_time | AW2: moa_recovery | AX2: moa_recovery_delay | AY2: aim_assist_hip_fire_radius | AZ2: aim_assist_ads_enter_raidus | BA2: aim_assist_ads_fire_radius | BB2: aim_assist_keep_fire | BC2: aim_assist_keep_recover_time | BD2: aim_assist_duration | BE2: burst_shot_count | BF2: burst_interval | BG2: burst_min_input_interval | BH2: burst_final_shot_modifier | BI2: pellet_count | BJ2: pellet_spread | BK2: heat_max | BL2: heat_per_shot | BM2: heat_cooldown_rate | BN2: heat_cooldown_delay | BO2: overheat_cooldown_time | BP2: post_fire_delay | BQ2: force_delay_rate | BR2: draw_duration | BS2: fire_hit_energy_gain | BT2: energy_gain_head_modifier | BU2: autofire_radius | BV2: autofire_trigger_timer | BW2: autofire_grace_timer | BX2: charge_max_time | BY2: charge_tier | BZ2: charge_damage_modifier_per_tier | CA2: charge_damage_modifier_max | CB2: charge_ammo_consume_modifier_per_tier
A3: 210011 | B3: =_xlfn.XLOOKUP(WeaponStat[[#This Row],[id]],Weapon[[#This Row],[id]],Weapon[[#This Row],['#group_memo]]) | C3: =_xlfn.XLOOKUP(WeaponStat[[#This Row],[id]],Weapon[[#This Row],[id]],Weapon[[#This Row],['#name_memo]]) | D3: 10 | E3: 17500 | F3: 10000 | G3: 8500 | H3: 10000 | I3: 0 | J3: 0 | K3: 10000 | L3: 0 | M3: 100 | N3: 20000 | O3: 1250 | P3: 2500 | Q3: 4000 | R3: 8 | S3: 8 | T3: 10 | U3: 1800 | V3: 1600 | W3: 9999 | X3: 9999 | Y3: 400 | Z3: 10000 | AA3: 6000 | AB3: 4000 | AC3: 3000 | AD3: 8000 | AE3: 8000 | AF3: 5000 | AG3: 3000 | AH3: 2500 | AI3: 2000 | AJ3: 4000 | AK3: 4000 | AL3: 10000 | AM3: 10000 | AN3: 10000 | AO3: 10000 | AP3: 10000 | AQ3: 10000 | AR3: 24 | AS3: 0 | AT3: 0 | AU3: 0 | AV3: 0 | AW3: 0 | AX3: 0 | AY3: 900 | AZ3: 1000 | BA3: 900 | BB3: 2 | BC3: 1000 | BD3: 500 | BE3: 0 | BF3: 0 | BG3: 0 | BH3: 0 | BI3: 10 | BJ3: 240 | BK3: 0 | BL3: 0 | BM3: 0 | BN3: 0 | BO3: 0 | BP3: 0 | BQ3: 9000 | BR3: 300 | BS3: 59 | BT3: 15000 | BU3: 450 | BV3: 0 | BW3: 150 | BX3: 0 | BY3: 0 | BZ3: 0 | CA3: 0 | CB3: 0
A4: 210012 | B4: =_xlfn.XLOOKUP(WeaponStat[[#This Row],[id]],Weapon[[#This Row],[id]],Weapon[[#This Row],['#group_memo]]) | C4: =_xlfn.XLOOKUP(WeaponStat[[#This Row],[id]],Weapon[[#This Row],[id]],Weapon[[#This Row],['#name_memo]]) | D4: 13 | E4: 17500 | F4: 10000 | G4: 8500 | H4: 10000 | I4: 0 | J4: 0 | K4: 10000 | L4: 0 | M4: 600 | N4: 20000 | O4: 2500 | P4: 5500 | Q4: 4000 | R4: 50 | S4: 45 | T4: 60 | U4: 1800 | V4: 1600 | W4: 9999 | X4: 9999 | Y4: 420 | Z4: 10000 | AA4: 6000 | AB4: 4000 | AC4: 3000 | AD4: 8000 | AE4: 8000 | AF4: 5000 | AG4: 3000 | AH4: 2500 | AI4: 2000 | AJ4: 4000 | AK4: 4000 | AL4: 10000 | AM4: 8500 | AN4: 8500 | AO4: 8500 | AP4: 11000 | AQ4: 13000 | AR4: 15 | AS4: 60 | AT4: 25 | AU4: 2 | AV4: 600 | AW4: 150 | AX4: 300 | AY4: 900 | AZ4: 1000 | BA4: 900 | BB4: 15 | BC4: 1000 | BD4: 500 | BE4: 0 | BF4: 0 | BG4: 0 | BH4: 0 | BI4: 0 | BJ4: 0 | BK4: 0 | BL4: 0 | BM4: 0 | BN4: 0 | BO4: 0 | BP4: 0 | BQ4: 9000 | BR4: 300 | BS4: 87 | BT4: 15000 | BU4: 450 | BV4: 0 | BW4: 150 | BX4: 0 | BY4: 0 | BZ4: 0 | CA4: 0 | CB4: 0
A5: 210013 | B5: =_xlfn.XLOOKUP(WeaponStat[[#This Row],[id]],Weapon[[#This Row],[id]],Weapon[[#This Row],['#group_memo]]) | C5: =_xlfn.XLOOKUP(WeaponStat[[#This Row],[id]],Weapon[[#This Row],[id]],Weapon[[#This Row],['#name_memo]]) | D5: 35 | E5: 17500 | F5: 10000 | G5: 8500 | H5: 7000 | I5: 0 | J5: 0 | K5: 10000 | L5: 0 | M5: 210 | N5: 20000 | O5: 2500 | P5: 4500 | Q5: 3000 | R5: 14 | S5: 21 | T5: 28 | U5: 1500 | V5: 1500 | W5: 9999 | X5: 9999 | Y5: 470 | Z5: 10000 | AA5: 6000 | AB5: 4000 | AC5: 3000 | AD5: 8000 | AE5: 8000 | AF5: 5000 | AG5: 3000 | AH5: 2500 | AI5: 2000 | AJ5: 4000 | AK5: 4000 | AL5: 10000 | AM5: 8500 | AN5: 8500 | AO5: 8500 | AP5: 11000 | AQ5: 13000 | AR5: 12 | AS5: 50 | AT5: 12 | AU5: 2 | AV5: 600 | AW5: 150 | AX5: 300 | AY5: 900 | AZ5: 1000 | BA5: 900 | BB5: 4 | BC5: 1000 | BD5: 500 | BE5: 0 | BF5: 0 | BG5: 0 | BH5: 0 | BI5: 0 | BJ5: 0 | BK5: 0 | BL5: 0 | BM5: 0 | BN5: 0 | BO5: 0 | BP5: 0 | BQ5: 9000 | BR5: 300 | BS5: 97 | BT5: 15000 | BU5: 450 | BV5: 150 | BW5: 300 | BX5: 0 | BY5: 0 | BZ5: 0 | CA5: 0 | CB5: 0
A6: 210014 | B6: =_xlfn.XLOOKUP(WeaponStat[[#This Row],[id]],Weapon[[#This Row],[id]],Weapon[[#This Row],['#group_memo]]) | C6: =_xlfn.XLOOKUP(WeaponStat[[#This Row],[id]],Weapon[[#This Row],[id]],Weapon[[#This Row],['#name_memo]]) | D6: 0 | E6: 0 | F6: 0 | G6: 0 | H6: 0 | I6: 0 | J6: 0 | K6: 10000 | L6: 0 | M6: 0 | N6: 0 | O6: 0 | P6: 0 | Q6: 0 | R6: 0 | S6: 0 | T6: 0 | U6: 0 | V6: 0 | W6: 0 | X6: 0 | Y6: 150 | Z6: 10000 | AA6: 6000 | AB6: 4000 | AC6: 3000 | AD6: 8000 | AE6: 8000 | AF6: 5000 | AG6: 3000 | AH6: 2500 | AI6: 2000 | AJ6: 4000 | AK6: 4000 | AL6: 0 | AM6: 0 | AN6: 0 | AO6: 0 | AP6: 0 | AQ6: 0 | AR6: 0 | AS6: 0 | AT6: 0 | AU6: 0 | AV6: 0 | AW6: 0 | AX6: 0 | AY6: 0 | AZ6: 0 | BA6: 0 | BB6: 0 | BC6: 0 | BD6: 0 | BE6: 0 | BF6: 0 | BG6: 0 | BH6: 0 | BI6: 0 | BJ6: 0 | BK6: 0 | BL6: 0 | BM6: 0 | BN6: 0 | BO6: 0 | BP6: 0 | BQ6: 9000 | BR6: 600 | BS6: 0 | BT6: 0 | BU6: 0 | BV6: 0 | BW6: 0 | BX6: 0 | BY6: 0 | BZ6: 0 | CA6: 0 | CB6: 0
A7: 220011 | B7: =_xlfn.XLOOKUP(WeaponStat[[#This Row],[id]],Weapon[[#This Row],[id]],Weapon[[#This Row],['#group_memo]]) | C7: =_xlfn.XLOOKUP(WeaponStat[[#This Row],[id]],Weapon[[#This Row],[id]],Weapon[[#This Row],['#name_memo]]) | D7: 21 | E7: 17500 | F7: 10000 | G7: 8500 | H7: 10000 | I7: 0 | J7: 0 | K7: 10000 | L7: 0 | M7: 450 | N7: 20000 | O7: 2500 | P7: 4500 | Q7: 4000 | R7: 30 | S7: 45 | T7: 60 | U7: 1800 | V7: 1800 | W7: 9999 | X7: 9999 | Y7: 400 | Z7: 10000 | AA7: 6000 | AB7: 4000 | AC7: 3000 | AD7: 8000 | AE7: 8000 | AF7: 5000 | AG7: 3000 | AH7: 2500 | AI7: 2000 | AJ7: 4000 | AK7: 4000 | AL7: 10000 | AM7: 8500 | AN7: 8500 | AO7: 8500 | AP7: 12000 | AQ7: 15000 | AR7: 15 | AS7: 50 | AT7: 8 | AU7: 3 | AV7: 600 | AW7: 150 | AX7: 300 | AY7: 900 | AZ7: 1000 | BA7: 900 | BB7: 12 | BC7: 800 | BD7: 500 | BE7: 0 | BF7: 0 | BG7: 0 | BH7: 0 | BI7: 0 | BJ7: 0 | BK7: 0 | BL7: 0 | BM7: 0 | BN7: 0 | BO7: 0 | BP7: 0 | BQ7: 9000 | BR7: 500 | BS7: 115 | BT7: 15000 | BU7: 450 | BV7: 0 | BW7: 150 | BX7: 0 | BY7: 0 | BZ7: 0 | CA7: 0 | CB7: 0
A8: 220012 | B8: =_xlfn.XLOOKUP(WeaponStat[[#This Row],[id]],Weapon[[#This Row],[id]],Weapon[[#This Row],['#group_memo]]) | C8: =_xlfn.XLOOKUP(WeaponStat[[#This Row],[id]],Weapon[[#This Row],[id]],Weapon[[#This Row],['#name_memo]]) | D8: 16 | E8: 15000 | F8: 10000 | G8: 8500 | H8: 13000 | I8: 0 | J8: 0 | K8: 10000 | L8: 0 | M8: 630 | N8: 20000 | O8: 2000 | P8: 4000 | Q8: 4000 | R8: 75 | S8: 113 | T8: 150 | U8: 2800 | V8: 2800 | W8: 9999 | X8: 9999 | Y8: 335 | Z8: 10000 | AA8: 5500 | AB8: 4000 | AC8: 3000 | AD8: 8000 | AE8: 8000 | AF8: 5000 | AG8: 3000 | AH8: 2500 | AI8: 2000 | AJ8: 4000 | AK8: 4000 | AL8: 10000 | AM8: 7000 | AN8: 8500 | AO8: 8500 | AP8: 12000 | AQ8: 15000 | AR8: 20 | AS8: 80 | AT8: 25 | AU8: 2 | AV8: 600 | AW8: 200 | AX8: 300 | AY8: 900 | AZ8: 1000 | BA8: 900 | BB8: 16 | BC8: 800 | BD8: 500 | BE8: 0 | BF8: 0 | BG8: 0 | BH8: 0 | BI8: 0 | BJ8: 0 | BK8: 0 | BL8: 0 | BM8: 0 | BN8: 0 | BO8: 0 | BP8: 0 | BQ8: 9000 | BR8: 500 | BS8: 134 | BT8: 15000 | BU8: 450 | BV8: 0 | BW8: 150 | BX8: 0 | BY8: 0 | BZ8: 0 | CA8: 0 | CB8: 0
A9: 220013 | B9: =_xlfn.XLOOKUP(WeaponStat[[#This Row],[id]],Weapon[[#This Row],[id]],Weapon[[#This Row],['#group_memo]]) | C9: =_xlfn.XLOOKUP(WeaponStat[[#This Row],[id]],Weapon[[#This Row],[id]],Weapon[[#This Row],['#name_memo]]) | D9: 50 | E9: 25000 | F9: 10000 | G9: 8500 | H9: 10000 | I9: 0 | J9: 0 | K9: 10000 | L9: 0 | M9: 105 | N9: 20000 | O9: 2500 | P9: 4500 | Q9: 3000 | R9: 7 | S9: 11 | T9: 14 | U9: 1600 | V9: 1600 | W9: 9999 | X9: 9999 | Y9: 470 | Z9: 10000 | AA9: 6000 | AB9: 4000 | AC9: 3000 | AD9: 8000 | AE9: 8000 | AF9: 5000 | AG9: 3000 | AH9: 2500 | AI9: 2000 | AJ9: 4000 | AK9: 4000 | AL9: 10000 | AM9: 8500 | AN9: 8500 | AO9: 8500 | AP9: 11000 | AQ9: 13000 | AR9: 10 | AS9: 10 | AT9: 0 | AU9: 0 | AV9: 0 | AW9: 0 | AX9: 0 | AY9: 900 | AZ9: 1000 | BA9: 900 | BB9: 2 | BC9: 800 | BD9: 500 | BE9: 0 | BF9: 0 | BG9: 0 | BH9: 0 | BI9: 0 | BJ9: 0 | BK9: 0 | BL9: 0 | BM9: 0 | BN9: 0 | BO9: 0 | BP9: 0 | BQ9: 9000 | BR9: 300 | BS9: 286 | BT9: 15000 | BU9: 450 | BV9: 0 | BW9: 150 | BX9: 0 | BY9: 0 | BZ9: 0 | CA9: 0 | CB9: 0
A10: 220014 | B10: =_xlfn.XLOOKUP(WeaponStat[[#This Row],[id]],Weapon[[#This Row],[id]],Weapon[[#This Row],['#group_memo]]) | C10: =_xlfn.XLOOKUP(WeaponStat[[#This Row],[id]],Weapon[[#This Row],[id]],Weapon[[#This Row],['#name_memo]]) | D10: 100 | E10: 10000 | F10: 10000 | G10: 10000 | H10: 18000 | I10: 0 | J10: 0 | K10: 10000 | L10: 0 | M10: 100 | N10: 20000 | O10: 5000 | P10: 5000 | Q10: 10000 | R10: 6 | S10: 6 | T10: 6 | U10: 2000 | V10: 2000 | W10: 6 | X10: 8 | Y10: 350 | Z10: 10000 | AA10: 6000 | AB10: 4000 | AC10: 3000 | AD10: 8000 | AE10: 4000 | AF10: 5000 | AG10: 3000 | AH10: 2500 | AI10: 2000 | AJ10: 4000 | AK10: 4000 | AL10: 10000 | AM10: 10000 | AN10: 10000 | AO10: 10000 | AP10: 10000 | AQ10: 10000 | AR10: 0 | AS10: 0 | AT10: 0 | AU10: 0 | AV10: 0 | AW10: 0 | AX10: 0 | AY10: 0 | AZ10: 0 | BA10: 0 | BB10: 0 | BC10: 0 | BD10: 500 | BE10: 0 | BF10: 0 | BG10: 0 | BH10: 0 | BI10: 0 | BJ10: 0 | BK10: 0 | BL10: 0 | BM10: 0 | BN10: 0 | BO10: 0 | BP10: 0 | BQ10: 0 | BR10: 900 | BS10: 0 | BT10: 0 | BU10: 450 | BV10: 0 | BW10: 150 | BX10: 0 | BY10: 0 | BZ10: 0 | CA10: 0 | CB10: 0
A11: 230011 | B11: =_xlfn.XLOOKUP(WeaponStat[[#This Row],[id]],Weapon[[#This Row],[id]],Weapon[[#This Row],['#group_memo]]) | C11: =_xlfn.XLOOKUP(WeaponStat[[#This Row],[id]],Weapon[[#This Row],[id]],Weapon[[#This Row],['#name_memo]]) | D11: 15 | E11: 17500 | F11: 10000 | G11: 8500 | H11: 7000 | I11: 0 | J11: 0 | K11: 10000 | L11: 0 | M11: 850 | N11: 20000 | O11: 1500 | P11: 3000 | Q11: 4000 | R11: 25 | S11: 30 | T11: 35 | U11: 1600 | V11: 1600 | W11: 9999 | X11: 9999 | Y11: 430 | Z11: 10000 | AA11: 6000 | AB11: 4000 | AC11: 3000 | AD11: 8000 | AE11: 8000 | AF11: 5000 | AG11: 3000 | AH11: 2500 | AI11: 2000 | AJ11: 4000 | AK11: 4000 | AL11: 10000 | AM11: 8500 | AN11: 8500 | AO11: 8500 | AP11: 12000 | AQ11: 15000 | AR11: 35 | AS11: 100 | AT11: 25 | AU11: 1 | AV11: 600 | AW11: 300 | AX11: 600 | AY11: 900 | AZ11: 1000 | BA11: 900 | BB11: 7 | BC11: 1000 | BD11: 500 | BE11: 0 | BF11: 0 | BG11: 0 | BH11: 0 | BI11: 0 | BJ11: 0 | BK11: 0 | BL11: 0 | BM11: 0 | BN11: 0 | BO11: 0 | BP11: 0 | BQ11: 9000 | BR11: 500 | BS11: 50 | BT11: 15000 | BU11: 450 | BV11: 0 | BW11: 150 | BX11: 0 | BY11: 0 | BZ11: 0 | CA11: 0 | CB11: 0
A12: 230012 | B12: =_xlfn.XLOOKUP(WeaponStat[[#This Row],[id]],Weapon[[#This Row],[id]],Weapon[[#This Row],['#group_memo]]) | C12: =_xlfn.XLOOKUP(WeaponStat[[#This Row],[id]],Weapon[[#This Row],[id]],Weapon[[#This Row],['#name_memo]]) | D12: 234 | E12: 15000 | F12: 10000 | G12: 8500 | H12: 7000 | I12: 0 | J12: 0 | K12: 10000 | L12: 0 | M12: 75 | N12: 20000 | O12: 5000 | P12: 5000 | Q12: 10000 | R12: 5 | S12: 8 | T12: 10 | U12: 2600 | V12: 2600 | W12: 9999 | X12: 9999 | Y12: 400 | Z12: 10000 | AA12: 6000 | AB12: 4000 | AC12: 3000 | AD12: 8000 | AE12: 8000 | AF12: 5000 | AG12: 3000 | AH12: 2500 | AI12: 2000 | AJ12: 4000 | AK12: 4000 | AL12: 10000 | AM12: 7000 | AN12: 1000 | AO12: 1000 | AP12: 12000 | AQ12: 15000 | AR12: 2 | AS12: 16 | AT12: 1 | AU12: 1 | AV12: 400 | AW12: 300 | AX12: 600 | AY12: 900 | AZ12: 1000 | BA12: 900 | BB12: 1 | BC12: 1000 | BD12: 500 | BE12: 0 | BF12: 0 | BG12: 0 | BH12: 0 | BI12: 0 | BJ12: 0 | BK12: 0 | BL12: 0 | BM12: 0 | BN12: 0 | BO12: 0 | BP12: 0 | BQ12: 9000 | BR12: 500 | BS12: 500 | BT12: 15000 | BU12: 450 | BV12: 0 | BW12: 150 | BX12: 0 | BY12: 0 | BZ12: 0 | CA12: 0 | CB12: 0
A13: 230013 | B13: =_xlfn.XLOOKUP(WeaponStat[[#This Row],[id]],Weapon[[#This Row],[id]],Weapon[[#This Row],['#group_memo]]) | C13: =_xlfn.XLOOKUP(WeaponStat[[#This Row],[id]],Weapon[[#This Row],[id]],Weapon[[#This Row],['#name_memo]]) | D13: 24 | E13: 15000 | F13: 10000 | G13: 8500 | H13: 10000 | I13: 0 | J13: 0 | K13: 10000 | L13: 0 | M13: 385 | N13: 20000 | O13: 3000 | P13: 5000 | Q13: 2000 | R13: 9 | S13: 14 | T13: 18 | U13: 1800 | V13: 1800 | W13: 9999 | X13: 9999 | Y13: 470 | Z13: 10000 | AA13: 6000 | AB13: 4000 | AC13: 3000 | AD13: 8000 | AE13: 8000 | AF13: 5000 | AG13: 3000 | AH13: 2500 | AI13: 2000 | AJ13: 4000 | AK13: 4000 | AL13: 10000 | AM13: 8500 | AN13: 8500 | AO13: 8500 | AP13: 12000 | AQ13: 15000 | AR13: 17 | AS13: 136 | AT13: 9 | AU13: 2 | AV13: 600 | AW13: 250 | AX13: 600 | AY13: 900 | AZ13: 1000 | BA13: 900 | BB13: 2 | BC13: 1000 | BD13: 500 | BE13: 0 | BF13: 0 | BG13: 0 | BH13: 0 | BI13: 0 | BJ13: 0 | BK13: 0 | BL13: 0 | BM13: 0 | BN13: 0 | BO13: 0 | BP13: 0 | BQ13: 9000 | BR13: 300 | BS13: 100 | BT13: 15000 | BU13: 450 | BV13: 0 | BW13: 150 | BX13: 0 | BY13: 0 | BZ13: 0 | CA13: 0 | CB13: 0
A14: 230014 | B14: =_xlfn.XLOOKUP(WeaponStat[[#This Row],[id]],Weapon[[#This Row],[id]],Weapon[[#This Row],['#group_memo]]) | C14: =_xlfn.XLOOKUP(WeaponStat[[#This Row],[id]],Weapon[[#This Row],[id]],Weapon[[#This Row],['#name_memo]]) | D14: 25 | E14: 10000 | F14: 10000 | G14: 10000 | H14: 10000 | I14: 0 | J14: 0 | K14: 10000 | L14: 0 | M14: 125 | N14: 20000 | O14: 5000 | P14: 5000 | Q14: 10000 | R14: 1 | S14: 1 | T14: 1 | U14: 1600 | V14: 1600 | W14: 1 | X14: 1 | Y14: 410 | Z14: 10000 | AA14: 6000 | AB14: 4000 | AC14: 3000 | AD14: 8000 | AE14: 8000 | AF14: 5000 | AG14: 3000 | AH14: 2500 | AI14: 2000 | AJ14: 4000 | AK14: 4000 | AL14: 10000 | AM14: 8500 | AN14: 8500 | AO14: 8500 | AP14: 12000 | AQ14: 15000 | AR14: 0 | AS14: 0 | AT14: 0 | AU14: 0 | AV14: 0 | AW14: 0 | AX14: 0 | AY14: 900 | AZ14: 1000 | BA14: 900 | BB14: 1 | BC14: 1000 | BD14: 500 | BE14: 0 | BF14: 0 | BG14: 0 | BH14: 0 | BI14: 0 | BJ14: 0 | BK14: 0 | BL14: 0 | BM14: 0 | BN14: 0 | BO14: 0 | BP14: 0 | BQ14: 0 | BR14: 500 | BS14: 0 | BT14: 0 | BU14: 0 | BV14: 0 | BW14: 150 | BX14: 0 | BY14: 0 | BZ14: 0 | CA14: 0 | CB14: 0
... A22: 240016 | B22: =_xlfn.XLOOKUP(WeaponStat[[#This Row],[id]],Weapon[[#This Row],[id]],Weapon[[#This Row],['#group_memo]]) | C22: =_xlfn.XLOOKUP(WeaponStat[[#This Row],[id]],Weapon[[#This Row],[id]],Weapon[[#This Row],['#name_memo]]) | D22: 0 | E22: 10000 | F22: 10000 | G22: 10000 | H22: 10000 | I22: 0 | J22: 0 | K22: 10000 | L22: 0 | M22: 125 | N22: 20000 | O22: 2500 | P22: 2500 | Q22: 10000 | R22: 1 | S22: 1 | T22: 1 | U22: 2400 | V22: 2400 | W22: 1 | X22: 1 | Y22: 440 | Z22: 10000 | AA22: 6000 | AB22: 4000 | AC22: 3000 | AD22: 8000 | AE22: 8000 | AF22: 5000 | AG22: 3000 | AH22: 2500 | AI22: 2000 | AJ22: 4000 | AK22: 4000 | AL22: 10000 | AM22: 8500 | AN22: 8500 | AO22: 8500 | AP22: 12000 | AQ22: 15000 | AR22: 0 | AS22: 0 | AT22: 0 | AU22: 0 | AV22: 0 | AW22: 0 | AX22: 0 | AY22: 0 | AZ22: 0 | BA22: 0 | BB22: 0 | BC22: 0 | BD22: 0 | BE22: 0 | BF22: 0 | BG22: 0 | BH22: 0 | BI22: 0 | BJ22: 0 | BK22: 0 | BL22: 0 | BM22: 0 | BN22: 0 | BO22: 0 | BP22: 0 | BQ22: 9000 | BR22: 300 | BS22: 0 | BT22: 0 | BU22: 0 | BV22: 0 | BW22: 0 | BX22: 0 | BY22: 0 | BZ22: 0 | CA22: 0 | CB22: 0

Sheet WeaponSelfStat
A1: DataGroup | B1: WeaponSelfStat
A2: id | B2: #weapon_self_memo | C2: max_health | D2: health_regen | E2: max_innate_shield | F2: innate_shield_regen_draw | G2: innate_shield_regen_sheath | H2: heal_rate | I2: heal_by_rate | J2: temp_shield_rate | K2: temp_shield_by_rate | L2: damage_reduction_rate | M2: bullet_damage_reduction_rate | N2: splash_damage_reduction_rate | O2: skill_damage_reduction_rate
A3: 210014 | B3: 뱅가드_전술방패 | C3: 0 | D3: 0 | E3: 800 | F3: 0 | G3: 160 | H3: 0 | I3: 0 | J3: 0 | K3: 0 | L3: 0 | M3: 0 | N3: 0 | O3: 0

Sheet WeaponStatDisplay
A1: DataGroup | B1: WeaponStatDisplay
A2: weapon_type | B2: #name_memo | C2: ui_sort_order | D2: stat_type
A3: HG | B3: 피해량 | C3: 1 | D3: DamageBase
A4: HG | B4: 연사력 | C4: 2 | D4: FireRate
A5: HG | B5: 장탄량 | C5: 3 | D5: MagCapacity1
A6: HG | B6: 보호막 피해율 | C6: 4 | D6: DamageShieldModifier
A7: HG | B7: 헤드샷 배율 | C7: 5 | D7: DamageHeadModifier
A8: HG | B8: 재장전 시간 | C8: 6 | D8: ReloadTime
A9: HG | B9: 유효 사거리 | C9: 7 | D9: DamageFalloffStartDistance
A10: HG | B10: 정확도 | C10: 8 | D10: MoaMax
A11: AR | B11: 피해량 | C11: 1 | D11: DamageBase
A12: AR | B12: 연사력 | C12: 2 | D12: FireRate
A13: AR | B13: 장탄량 | C13: 3 | D13: MagCapacity1
A14: AR | B14: 보호막 피해율 | C14: 4 | D14: DamageShieldModifier
... A69: PreCharge | B69: 최대 충전시 피해증가 | C69: 8 | D69: ChargeDamageModifierMax

Sheet #DamageToEnergyGain
A1: shield | B1: 200 | C1: 스트라이커 1명을 죽일 때 필요한 사격 수 & TTK 와 그때 N% 비율의 궁극기를 채우기 위해 필요한 발 당 명중시 에너지 획득량
A2: HP | B2: 250
A3: G-MAX | B3: 12000
A4: Kill_to_max_rate | B4: 0.12
A5: heal_weapon | B5: 0.01 | F5: 노란색 셀은 직접 입력
I6: 펠렛 명중률 가정치 | U6: 1탄창으로 죽이는 비율
A7: id | B7: #group_memo | C7: #name_memo | D7: damage_base | E7: damage_shield_modifier | F7: fire_rate | G7: mag_capacity_1 | H7: pellet_count | I7: pellet_hit_rate | K7: need_to_shield | L7: RoundUP | N7: left_count | O7: left_to_hp | Q7: neet_to_hp | R7: RoundUP | T7: sum_count_to_kill | U7: mag1_coverage | V7: TTK | W7: TTK_Rank | Y7: sum_count_to_EGain
A8: =WeaponStat!A3 | B8: =WeaponStat!B3 | C8: =WeaponStat!C3 | D8: =_xlfn.XLOOKUP(A8,WeaponStat[id],WeaponStat[damage_base],,0) | E8: =_xlfn.XLOOKUP(A8,WeaponStat[id],WeaponStat[damage_shield_modifier],,0) | F8: =_xlfn.XLOOKUP(A8,WeaponStat[id],WeaponStat[fire_rate],,0) | G8: =_xlfn.XLOOKUP(A8,WeaponStat[id],WeaponStat[mag_capacity_1],,0) | H8: =WeaponStat!BI3 | I8: 0.8 | K8: =$B$1/((D8*H8*I8)*(E8/10000)) | L8: =ROUNDUP(K8,0) | N8: =MOD(K8,1) | O8: =N8*(D8*H8*I8) | Q8: =($B$2-O8)/((D8*H8*I8)*(E8/10000)) | R8: =ROUNDUP(Q8,0) | T8: =Q8+K8 | U8: =IFERROR(IF(G8>0,G8/T8,0),0) | V8: =IFERROR((60/F8)*T8,0) | W8: =_xlfn.LET(_xlpm.x,$V$8:$V$22,COUNT(_xlpm.x)-_xlfn.RANK.EQ(V8,_xlpm.x)) | Y8: =IFERROR(ROUNDUP($B$3/(T8*(H8*I8)/$B$4),0),$B$5*$B$3) | AA8: 42 | AC8: =Y8/AA8-1
A9: =WeaponStat!A4 | B9: =WeaponStat!B4 | C9: =WeaponStat!C4 | D9: =_xlfn.XLOOKUP(A9,WeaponStat[id],WeaponStat[damage_base],,0) | E9: =_xlfn.XLOOKUP(A9,WeaponStat[id],WeaponStat[damage_shield_modifier],,0) | F9: =_xlfn.XLOOKUP(A9,WeaponStat[id],WeaponStat[fire_rate],,0) | G9: =_xlfn.XLOOKUP(A9,WeaponStat[id],WeaponStat[mag_capacity_1],,0) | H9: 1 | I9: 1 | K9: =$B$1/((D9*H9*I9)*(E9/10000)) | L9: =ROUNDUP(K9,0) | N9: =MOD(K9,1) | O9: =N9*(D9*H9*I9) | Q9: =($B$2-O9)/((D9*H9*I9)*(E9/10000)) | R9: =ROUNDUP(Q9,0) | T9: =Q9+K9 | U9: =IFERROR(IF(G9>0,G9/T9,0),0) | V9: =IFERROR((60/F9)*T9,0) | W9: =_xlfn.LET(_xlpm.x,$V$8:$V$22,COUNT(_xlpm.x)-_xlfn.RANK.EQ(V9,_xlpm.x)) | Y9: =IFERROR(ROUNDUP($B$3/(T9*(H9*I9)/$B$4),0),$B$5*$B$3) | AA9: 87 | AC9: =Y9/AA9-1
A10: =WeaponStat!A5 | B10: =WeaponStat!B5 | C10: =WeaponStat!C5 | D10: =_xlfn.XLOOKUP(A10,WeaponStat[id],WeaponStat[damage_base],,0) | E10: =_xlfn.XLOOKUP(A10,WeaponStat[id],WeaponStat[damage_shield_modifier],,0) | F10: =_xlfn.XLOOKUP(A10,WeaponStat[id],WeaponStat[fire_rate],,0) | G10: =_xlfn.XLOOKUP(A10,WeaponStat[id],WeaponStat[mag_capacity_1],,0) | H10: 1 | I10: 1 | K10: =$B$1/((D10*H10*I10)*(E10/10000)) | L10: =ROUNDUP(K10,0) | N10: =MOD(K10,1) | O10: =N10*(D10*H10*I10) | Q10: =($B$2-O10)/((D10*H10*I10)*(E10/10000)) | R10: =ROUNDUP(Q10,0) | T10: =Q10+K10 | U10: =IFERROR(IF(G10>0,G10/T10,0),0) | V10: =IFERROR((60/F10)*T10,0) | W10: =_xlfn.LET(_xlpm.x,$V$8:$V$22,COUNT(_xlpm.x)-_xlfn.RANK.EQ(V10,_xlpm.x)) | Y10: =IFERROR(ROUNDUP($B$3/(T10*(H10*I10)/$B$4),0),$B$5*$B$3) | AA10: 63 | AC10: =Y10/AA10-1
A11: =WeaponStat!A7 | B11: =WeaponStat!B7 | C11: =WeaponStat!C7 | D11: =_xlfn.XLOOKUP(A11,WeaponStat[id],WeaponStat[damage_base],,0) | E11: =_xlfn.XLOOKUP(A11,WeaponStat[id],WeaponStat[damage_shield_modifier],,0) | F11: =_xlfn.XLOOKUP(A11,WeaponStat[id],WeaponStat[fire_rate],,0) | G11: =_xlfn.XLOOKUP(A11,WeaponStat[id],WeaponStat[mag_capacity_1],,0) | H11: 1 | I11: 1 | K11: =$B$1/((D11*H11*I11)*(E11/10000)) | L11: =ROUNDUP(K11,0) | N11: =MOD(K11,1) | O11: =N11*(D11*H11*I11) | Q11: =($B$2-O11)/((D11*H11*I11)*(E11/10000)) | R11: =ROUNDUP(Q11,0) | T11: =Q11+K11 | U11: =IFERROR(IF(G11>0,G11/T11,0),0) | V11: =IFERROR((60/F11)*T11,0) | W11: =_xlfn.LET(_xlpm.x,$V$8:$V$22,COUNT(_xlpm.x)-_xlfn.RANK.EQ(V11,_xlpm.x)) | Y11: =IFERROR(ROUNDUP($B$3/(T11*(H11*I11)/$B$4),0),$B$5*$B$3) | AA11: 87 | AC11: =Y11/AA11-1
A12: =WeaponStat!A8 | B12: =WeaponStat!B8 | C12: =WeaponStat!C8 | D12: =_xlfn.XLOOKUP(A12,WeaponStat[id],WeaponStat[damage_base],,0) | E12: =_xlfn.XLOOKUP(A12,WeaponStat[id],WeaponStat[damage_shield_modifier],,0) | F12: =_xlfn.XLOOKUP(A12,WeaponStat[id],WeaponStat[fire_rate],,0) | G12: =_xlfn.XLOOKUP(A12,WeaponStat[id],WeaponStat[mag_capacity_1],,0) | H12: 1 | I12: 1 | K12: =$B$1/((D12*H12*I12)*(E12/10000)) | L12: =ROUNDUP(K12,0) | N12: =MOD(K12,1) | O12: =N12*(D12*H12*I12) | Q12: =($B$2-O12)/((D12*H12*I12)*(E12/10000)) | R12: =ROUNDUP(Q12,0) | T12: =Q12+K12 | U12: =IFERROR(IF(G12>0,G12/T12,0),0) | V12: =IFERROR((60/F12)*T12,0) | W12: =_xlfn.LET(_xlpm.x,$V$8:$V$22,COUNT(_xlpm.x)-_xlfn.RANK.EQ(V12,_xlpm.x)) | Y12: =IFERROR(ROUNDUP($B$3/(T12*(H12*I12)/$B$4),0),$B$5*$B$3) | AA12: 134 | AC12: =Y12/AA12-1
A13: =WeaponStat!A9 | B13: =WeaponStat!B9 | C13: =WeaponStat!C9 | D13: =_xlfn.XLOOKUP(A13,WeaponStat[id],WeaponStat[damage_base],,0) | E13: =_xlfn.XLOOKUP(A13,WeaponStat[id],WeaponStat[damage_shield_modifier],,0) | F13: =_xlfn.XLOOKUP(A13,WeaponStat[id],WeaponStat[fire_rate],,0) | G13: =_xlfn.XLOOKUP(A13,WeaponStat[id],WeaponStat[mag_capacity_1],,0) | H13: 1 | I13: 1 | K13: =$B$1/((D13*H13*I13)*(E13/10000)) | L13: =ROUNDUP(K13,0) | N13: =MOD(K13,1) | O13: =N13*(D13*H13*I13) | Q13: =($B$2-O13)/((D13*H13*I13)*(E13/10000)) | R13: =ROUNDUP(Q13,0) | T13: =Q13+K13 | U13: =IFERROR(IF(G13>0,G13/T13,0),0) | V13: =IFERROR((60/F13)*T13,0) | W13: =_xlfn.LET(_xlpm.x,$V$8:$V$22,COUNT(_xlpm.x)-_xlfn.RANK.EQ(V13,_xlpm.x)) | Y13: =IFERROR(ROUNDUP($B$3/(T13*(H13*I13)/$B$4),0),$B$5*$B$3) | AA13: 286 | AC13: =Y13/AA13-1
A14: =WeaponStat!A10 | B14: =WeaponStat!B10 | C14: =WeaponStat!C10 | D14: =_xlfn.XLOOKUP(A14,WeaponStat[id],WeaponStat[damage_base],,0) | E14: =_xlfn.XLOOKUP(A14,WeaponStat[id],WeaponStat[damage_shield_modifier],,0) | F14: =_xlfn.XLOOKUP(A14,WeaponStat[id],WeaponStat[fire_rate],,0) | G14: =_xlfn.XLOOKUP(A14,WeaponStat[id],WeaponStat[mag_capacity_1],,0) | H14: 1 | I14: 1 | K14: =$B$1/((D14*H14*I14)*(E14/10000)) | L14: =ROUNDUP(K14,0) | N14: =MOD(K14,1) | O14: =N14*(D14*H14*I14) | Q14: =($B$2-O14)/((D14*H14*I14)*(E14/10000)) | R14: =ROUNDUP(Q14,0) | T14: =Q14+K14 | U14: =IFERROR(IF(G14>0,G14/T14,0),0) | V14: =IFERROR((60/F14)*T14,0) | W14: =_xlfn.LET(_xlpm.x,$V$8:$V$22,COUNT(_xlpm.x)-_xlfn.RANK.EQ(V14,_xlpm.x)) | Y14: 0 | AA14: 0 | AC14: =Y14/AA14-1
A15: =WeaponStat!A11 | B15: =WeaponStat!B11 | C15: =WeaponStat!C11 | D15: =_xlfn.XLOOKUP(A15,WeaponStat[id],WeaponStat[damage_base],,0) | E15: =_xlfn.XLOOKUP(A15,WeaponStat[id],WeaponStat[damage_shield_modifier],,0) | F15: =_xlfn.XLOOKUP(A15,WeaponStat[id],WeaponStat[fire_rate],,0) | G15: =_xlfn.XLOOKUP(A15,WeaponStat[id],WeaponStat[mag_capacity_1],,0) | H15: 1 | I15: 1 | K15: =$B$1/((D15*H15*I15)*(E15/10000)) | L15: =ROUNDUP(K15,0) | N15: =MOD(K15,1) | O15: =N15*(D15*H15*I15) | Q15: =($B$2-O15)/((D15*H15*I15)*(E15/10000)) | R15: =ROUNDUP(Q15,0) | T15: =Q15+K15 | U15: =IFERROR(IF(G15>0,G15/T15,0),0) | V15: =IFERROR((60/F15)*T15,0) | W15: =_xlfn.LET(_xlpm.x,$V$8:$V$22,COUNT(_xlpm.x)-_xlfn.RANK.EQ(V15,_xlpm.x)) | Y15: =IFERROR(ROUNDUP($B$3/(T15*(H15*I15)/$B$4),0),$B$5*$B$3) | AA15: 50 | AC15: =Y15/AA15-1
A16: =WeaponStat!A12 | B16: =WeaponStat!B12 | C16: =WeaponStat!C12 | D16: =_xlfn.XLOOKUP(A16,WeaponStat[id],WeaponStat[damage_base],,0) | E16: =_xlfn.XLOOKUP(A16,WeaponStat[id],WeaponStat[damage_shield_modifier],,0) | F16: =_xlfn.XLOOKUP(A16,WeaponStat[id],WeaponStat[fire_rate],,0) | G16: =_xlfn.XLOOKUP(A16,WeaponStat[id],WeaponStat[mag_capacity_1],,0) | H16: 1 | I16: 1 | K16: =$B$1/((D16*H16*I16)*(E16/10000)) | L16: =ROUNDUP(K16,0) | N16: =MOD(K16,1) | O16: =N16*(D16*H16*I16) | Q16: =($B$2-O16)/((D16*H16*I16)*(E16/10000)) | R16: =ROUNDUP(Q16,0) | T16: =Q16+K16 | U16: =IFERROR(IF(G16>0,G16/T16,0),0) | V16: =IFERROR((60/F16)*T16,0) | W16: =_xlfn.LET(_xlpm.x,$V$8:$V$22,COUNT(_xlpm.x)-_xlfn.RANK.EQ(V16,_xlpm.x)) | Y16: =IFERROR(ROUNDUP($B$3/(T16*(H16*I16)/$B$4),0),$B$5*$B$3) | AA16: 500 | AC16: =Y16/AA16-1
A17: =WeaponStat!A13 | B17: =WeaponStat!B13 | C17: =WeaponStat!C13 | D17: =_xlfn.XLOOKUP(A17,WeaponStat[id],WeaponStat[damage_base],,0) | E17: =_xlfn.XLOOKUP(A17,WeaponStat[id],WeaponStat[damage_shield_modifier],,0) | F17: =_xlfn.XLOOKUP(A17,WeaponStat[id],WeaponStat[fire_rate],,0) | G17: =_xlfn.XLOOKUP(A17,WeaponStat[id],WeaponStat[mag_capacity_1],,0) | H17: 1 | I17: 1 | K17: =$B$1/((D17*H17*I17)*(E17/10000)) | L17: =ROUNDUP(K17,0) | N17: =MOD(K17,1) | O17: =N17*(D17*H17*I17) | Q17: =($B$2-O17)/((D17*H17*I17)*(E17/10000)) | R17: =ROUNDUP(Q17,0) | T17: =Q17+K17 | U17: =IFERROR(IF(G17>0,G17/T17,0),0) | V17: =IFERROR((60/F17)*T17,0) | W17: =_xlfn.LET(_xlpm.x,$V$8:$V$22,COUNT(_xlpm.x)-_xlfn.RANK.EQ(V17,_xlpm.x)) | Y17: =IFERROR(ROUNDUP($B$3/(T17*(H17*I17)/$B$4),0),$B$5*$B$3) | AA17: 100 | AC17: =Y17/AA17-1
A18: =WeaponStat!A14 | B18: =WeaponStat!B14 | C18: =WeaponStat!C14 | D18: =_xlfn.XLOOKUP(A18,WeaponStat[id],WeaponStat[damage_base],,0) | E18: =_xlfn.XLOOKUP(A18,WeaponStat[id],WeaponStat[damage_shield_modifier],,0) | F18: =_xlfn.XLOOKUP(A18,WeaponStat[id],WeaponStat[fire_rate],,0) | G18: =_xlfn.XLOOKUP(A18,WeaponStat[id],WeaponStat[mag_capacity_1],,0) | H18: 1 | I18: 1 | K18: =$B$1/((D18*H18*I18)*(E18/10000)) | L18: =ROUNDUP(K18,0) | N18: =MOD(K18,1) | O18: =N18*(D18*H18*I18) | Q18: =($B$2-O18)/((D18*H18*I18)*(E18/10000)) | R18: =ROUNDUP(Q18,0) | T18: =Q18+K18 | U18: =IFERROR(IF(G18>0,G18/T18,0),0) | V18: =IFERROR((60/F18)*T18,0) | W18: =_xlfn.LET(_xlpm.x,$V$8:$V$22,COUNT(_xlpm.x)-_xlfn.RANK.EQ(V18,_xlpm.x)) | Y18: 0 | AA18: 0 | AC18: =Y18/AA18-1
A19: =WeaponStat!A15 | B19: =WeaponStat!B15 | C19: =WeaponStat!C15 | D19: =_xlfn.XLOOKUP(A19,WeaponStat[id],WeaponStat[damage_base],,0) | E19: =_xlfn.XLOOKUP(A19,WeaponStat[id],WeaponStat[damage_shield_modifier],,0) | F19: =_xlfn.XLOOKUP(A19,WeaponStat[id],WeaponStat[fire_rate],,0) | G19: =_xlfn.XLOOKUP(A19,WeaponStat[id],WeaponStat[mag_capacity_1],,0) | H19: 1 | I19: 1 | K19: =$B$1/((D19*H19*I19)*(E19/10000)) | L19: =ROUNDUP(K19,0) | N19: =MOD(K19,1) | O19: =N19*(D19*H19*I19) | Q19: =($B$2-O19)/((D19*H19*I19)*(E19/10000)) | R19: =ROUNDUP(Q19,0) | T19: =Q19+K19 | U19: =IFERROR(IF(G19>0,G19/T19,0),0) | V19: =IFERROR((60/F19)*T19,0) | W19: =_xlfn.LET(_xlpm.x,$V$8:$V$22,COUNT(_xlpm.x)-_xlfn.RANK.EQ(V19,_xlpm.x)) | Y19: =IFERROR(ROUNDUP($B$3/(T19*(H19*I19)/$B$4),0),$B$5*$B$3) | AA19: 1000 | AC19: =Y19/AA19-1
A20: =WeaponStat!A17 | B20: =WeaponStat!B17 | C20: =WeaponStat!C17 | D20: =_xlfn.XLOOKUP(A20,WeaponStat[id],WeaponStat[damage_base],,0) | E20: =_xlfn.XLOOKUP(A20,WeaponStat[id],WeaponStat[damage_shield_modifier],,0) | F20: =ROUNDDOWN(60000/((80+80+WeaponStat!BF17)/3),0) | G20: =_xlfn.XLOOKUP(A20,WeaponStat[id],WeaponStat[mag_capacity_1],,0) | H20: 1 | I20: 1 | K20: =$B$1/((D20*H20*I20)*(E20/10000)) | L20: =ROUNDUP(K20,0) | N20: =MOD(K20,1) | O20: =N20*(D20*H20*I20) | Q20: =($B$2-O20)/((D20*H20*I20)*(E20/10000)) | R20: =ROUNDUP(Q20,0) | T20: =Q20+K20 | U20: =IFERROR(IF(G20>0,G20/T20,0),0) | V20: =IFERROR((60/F20)*T20,0) | W20: =_xlfn.LET(_xlpm.x,$V$8:$V$22,COUNT(_xlpm.x)-_xlfn.RANK.EQ(V20,_xlpm.x)) | Y20: =IFERROR(ROUNDUP($B$3/(T20*(H20*I20)/$B$4),0),$B$5*$B$3) | AA20: 87 | AC20: =Y20/AA20-1
A21: =WeaponStat!A18 | B21: =WeaponStat!B18 | C21: =WeaponStat!C18 | D21: =_xlfn.XLOOKUP(A21,WeaponStat[id],WeaponStat[damage_base],,0) | E21: =_xlfn.XLOOKUP(A21,WeaponStat[id],WeaponStat[damage_shield_modifier],,0) | F21: =_xlfn.XLOOKUP(A21,WeaponStat[id],WeaponStat[fire_rate],,0) | G21: =_xlfn.XLOOKUP(A21,WeaponStat[id],WeaponStat[mag_capacity_1],,0) | H21: 1 | I21: 1 | K21: =$B$1/((D21*H21*I21)*(E21/10000)) | L21: =ROUNDUP(K21,0) | N21: =MOD(K21,1) | O21: =N21*(D21*H21*I21) | Q21: =($B$2-O21)/((D21*H21*I21)*(E21/10000)) | R21: =ROUNDUP(Q21,0) | T21: =Q21+K21 | U21: =IFERROR(IF(G21>0,G21/T21,0),0) | V21: =IFERROR((60/F21)*T21,0) | W21: =_xlfn.LET(_xlpm.x,$V$8:$V$22,COUNT(_xlpm.x)-_xlfn.RANK.EQ(V21,_xlpm.x)) | Y21: =IFERROR(ROUNDUP($B$3/(T21*(H21*I21)/$B$4),0),$B$5*$B$3) | AA21: 106 | AC21: =Y21/AA21-1
